2024-08-29 15:48:52,902 - asyncio - DEBUG - Using selector: SelectSelector
2024-08-29 15:48:52,928 - httpx - DEBUG - load_ssl_context verify=True cert=None trust_env=True http2=False
2024-08-29 15:48:52,929 - httpx - DEBUG - load_verify_locations cafile='c:\\Users\\USER\\AppData\\Local\\Programs\\Python\\Python39\\lib\\site-packages\\certifi\\cacert.pem'
2024-08-29 15:48:52,937 - httpcore.connection - DEBUG - connect_tcp.started host='127.0.0.1' port=7860 local_address=None timeout=None socket_options=None
2024-08-29 15:48:52,937 - httpcore.connection - DEBUG - connect_tcp.complete return_value=<httpcore._backends.sync.SyncStream object at 0x0000021083CF4070>
2024-08-29 15:48:52,938 - httpcore.http11 - DEBUG - send_request_headers.started request=<Request [b'GET']>
2024-08-29 15:48:52,938 - httpcore.http11 - DEBUG - send_request_headers.complete
2024-08-29 15:48:52,938 - httpcore.http11 - DEBUG - send_request_body.started request=<Request [b'GET']>
2024-08-29 15:48:52,938 - httpcore.http11 - DEBUG - send_request_body.complete
2024-08-29 15:48:52,938 - httpcore.http11 - DEBUG - receive_response_headers.started request=<Request [b'GET']>
2024-08-29 15:48:52,939 - httpcore.http11 - DEBUG - receive_response_headers.complete return_value=(b'HTTP/1.1', 200, b'OK', [(b'date', b'Thu, 29 Aug 2024 06:48:52 GMT'), (b'server', b'uvicorn'), (b'content-length', b'4'), (b'content-type', b'application/json')])
2024-08-29 15:48:52,939 - httpx - INFO - HTTP Request: GET http://127.0.0.1:7860/startup-events "HTTP/1.1 200 OK"
2024-08-29 15:48:52,939 - httpcore.http11 - DEBUG - receive_response_body.started request=<Request [b'GET']>
2024-08-29 15:48:52,939 - httpcore.http11 - DEBUG - receive_response_body.complete
2024-08-29 15:48:52,939 - httpcore.http11 - DEBUG - response_closed.started
2024-08-29 15:48:52,939 - httpcore.http11 - DEBUG - response_closed.complete
2024-08-29 15:48:52,939 - httpcore.connection - DEBUG - close.started
2024-08-29 15:48:52,939 - httpcore.connection - DEBUG - close.complete
2024-08-29 15:48:52,960 - httpcore.connection - DEBUG - connect_tcp.complete return_value=<httpcore._backends.sync.SyncStream object at 0x0000021083B0AD90>
2024-08-29 15:48:52,960 - httpcore.connection - DEBUG - start_tls.started ssl_context=<ssl.SSLContext object at 0x00000210839FC140> server_hostname='checkip.amazonaws.com' timeout=3
2024-08-29 15:48:53,032 - botocore.hooks - DEBUG - Changing event name from creating-client-class.iot-data to creating-client-class.iot-data-plane
2024-08-29 15:48:53,033 - botocore.hooks - DEBUG - Changing event name from before-call.apigateway to before-call.api-gateway
2024-08-29 15:48:53,033 - botocore.hooks - DEBUG - Changing event name from request-created.machinelearning.Predict to request-created.machine-learning.Predict
2024-08-29 15:48:53,034 - botocore.hooks - DEBUG - Changing event name from before-parameter-build.autoscaling.CreateLaunchConfiguration to before-parameter-build.auto-scaling.CreateLaunchConfiguration
2024-08-29 15:48:53,034 - botocore.hooks - DEBUG - Changing event name from before-parameter-build.route53 to before-parameter-build.route-53
2024-08-29 15:48:53,034 - botocore.hooks - DEBUG - Changing event name from request-created.cloudsearchdomain.Search to request-created.cloudsearch-domain.Search
2024-08-29 15:48:53,034 - botocore.hooks - DEBUG - Changing event name from docs.*.autoscaling.CreateLaunchConfiguration.complete-section to docs.*.auto-scaling.CreateLaunchConfiguration.complete-section
2024-08-29 15:48:53,035 - botocore.hooks - DEBUG - Changing event name from before-parameter-build.logs.CreateExportTask to before-parameter-build.cloudwatch-logs.CreateExportTask
2024-08-29 15:48:53,035 - botocore.hooks - DEBUG - Changing event name from docs.*.logs.CreateExportTask.complete-section to docs.*.cloudwatch-logs.CreateExportTask.complete-section
2024-08-29 15:48:53,035 - botocore.hooks - DEBUG - Changing event name from before-parameter-build.cloudsearchdomain.Search to before-parameter-build.cloudsearch-domain.Search
2024-08-29 15:48:53,035 - botocore.hooks - DEBUG - Changing event name from docs.*.cloudsearchdomain.Search.complete-section to docs.*.cloudsearch-domain.Search.complete-section
2024-08-29 15:48:53,036 - botocore.utils - DEBUG - IMDS ENDPOINT: http://169.254.169.254/
2024-08-29 15:48:53,037 - botocore.credentials - DEBUG - Looking for credentials via: env
2024-08-29 15:48:53,037 - botocore.credentials - DEBUG - Looking for credentials via: assume-role
2024-08-29 15:48:53,037 - botocore.credentials - DEBUG - Looking for credentials via: assume-role-with-web-identity
2024-08-29 15:48:53,037 - botocore.credentials - DEBUG - Looking for credentials via: sso
2024-08-29 15:48:53,037 - botocore.credentials - DEBUG - Looking for credentials via: shared-credentials-file
2024-08-29 15:48:53,037 - botocore.credentials - DEBUG - Looking for credentials via: custom-process
2024-08-29 15:48:53,037 - botocore.credentials - DEBUG - Looking for credentials via: config-file
2024-08-29 15:48:53,037 - botocore.credentials - DEBUG - Looking for credentials via: ec2-credentials-file
2024-08-29 15:48:53,037 - botocore.credentials - DEBUG - Looking for credentials via: boto-config
2024-08-29 15:48:53,038 - botocore.credentials - DEBUG - Looking for credentials via: container-role
2024-08-29 15:48:53,038 - botocore.credentials - DEBUG - Looking for credentials via: iam-role
2024-08-29 15:48:53,038 - urllib3.connectionpool - DEBUG - Starting new HTTP connection (1): 169.254.169.254:80
2024-08-29 15:48:53,051 - httpcore.connection - DEBUG - connect_tcp.complete return_value=<httpcore._backends.sync.SyncStream object at 0x0000021083B21520>
2024-08-29 15:48:53,051 - httpcore.connection - DEBUG - start_tls.started ssl_context=<ssl.SSLContext object at 0x00000210839FC640> server_hostname='api.gradio.app' timeout=3
2024-08-29 15:48:53,067 - httpcore.connection - DEBUG - start_tls.complete return_value=<httpcore._backends.sync.SyncStream object at 0x0000021083B0AD60>
2024-08-29 15:48:53,067 - httpcore.http11 - DEBUG - send_request_headers.started request=<Request [b'GET']>
2024-08-29 15:48:53,068 - httpcore.http11 - DEBUG - send_request_headers.complete
2024-08-29 15:48:53,068 - httpcore.http11 - DEBUG - send_request_body.started request=<Request [b'GET']>
2024-08-29 15:48:53,068 - httpcore.http11 - DEBUG - send_request_body.complete
2024-08-29 15:48:53,068 - httpcore.http11 - DEBUG - receive_response_headers.started request=<Request [b'GET']>
2024-08-29 15:48:53,175 - httpcore.http11 - DEBUG - receive_response_headers.complete return_value=(b'HTTP/1.1', 200, b'', [(b'Date', b'Thu, 29 Aug 2024 06:48:52 GMT'), (b'Content-Type', b'text/plain;charset=UTF-8'), (b'Content-Length', b'12'), (b'Connection', b'keep-alive'), (b'Server', b'nginx'), (b'Vary', b'Origin'), (b'Vary', b'Access-Control-Request-Method'), (b'Vary', b'Access-Control-Request-Headers')])
2024-08-29 15:48:53,175 - httpx - INFO - HTTP Request: GET https://checkip.amazonaws.com/ "HTTP/1.1 200 "
2024-08-29 15:48:53,176 - httpcore.http11 - DEBUG - receive_response_body.started request=<Request [b'GET']>
2024-08-29 15:48:53,176 - httpcore.http11 - DEBUG - receive_response_body.complete
2024-08-29 15:48:53,176 - httpcore.http11 - DEBUG - response_closed.started
2024-08-29 15:48:53,176 - httpcore.http11 - DEBUG - response_closed.complete
2024-08-29 15:48:53,176 - httpcore.connection - DEBUG - close.started
2024-08-29 15:48:53,176 - httpcore.connection - DEBUG - close.complete
2024-08-29 15:48:53,178 - urllib3.connectionpool - DEBUG - Starting new HTTPS connection (1): huggingface.co:443
2024-08-29 15:48:53,385 - httpcore.connection - DEBUG - start_tls.complete return_value=<httpcore._backends.sync.SyncStream object at 0x0000021083B214F0>
2024-08-29 15:48:53,385 - httpcore.http11 - DEBUG - send_request_headers.started request=<Request [b'GET']>
2024-08-29 15:48:53,386 - httpcore.http11 - DEBUG - send_request_headers.complete
2024-08-29 15:48:53,386 - httpcore.http11 - DEBUG - send_request_body.started request=<Request [b'GET']>
2024-08-29 15:48:53,386 - httpcore.http11 - DEBUG - send_request_body.complete
2024-08-29 15:48:53,386 - httpcore.http11 - DEBUG - receive_response_headers.started request=<Request [b'GET']>
2024-08-29 15:48:53,440 - urllib3.connectionpool - DEBUG - https://huggingface.co:443 "HEAD /api/telemetry/gradio/initiated HTTP/1.1" 200 0
2024-08-29 15:48:53,558 - httpcore.http11 - DEBUG - receive_response_headers.complete return_value=(b'HTTP/1.1', 200, b'OK', [(b'Date', b'Thu, 29 Aug 2024 06:48:53 GMT'), (b'Content-Type', b'application/json'), (b'Content-Length', b'21'), (b'Connection', b'keep-alive'), (b'Server', b'nginx/1.18.0'), (b'Access-Control-Allow-Origin', b'*')])
2024-08-29 15:48:53,559 - httpx - INFO - HTTP Request: GET https://api.gradio.app/pkg-version "HTTP/1.1 200 OK"
2024-08-29 15:48:53,559 - httpcore.http11 - DEBUG - receive_response_body.started request=<Request [b'GET']>
2024-08-29 15:48:53,559 - httpcore.http11 - DEBUG - receive_response_body.complete
2024-08-29 15:48:53,559 - httpcore.http11 - DEBUG - response_closed.started
2024-08-29 15:48:53,559 - httpcore.http11 - DEBUG - response_closed.complete
2024-08-29 15:48:53,559 - httpcore.connection - DEBUG - close.started
2024-08-29 15:48:53,560 - httpcore.connection - DEBUG - close.complete
2024-08-29 15:48:54,042 - botocore.utils - DEBUG - Caught retryable HTTP exception while making metadata service request to http://169.254.169.254/latest/api/token: Connect timeout on endpoint URL: "http://169.254.169.254/latest/api/token"
Traceback (most recent call last):
  File "c:\Users\USER\AppData\Local\Programs\Python\Python39\lib\site-packages\urllib3\connection.py", line 174, in _new_conn
    conn = connection.create_connection(
  File "c:\Users\USER\AppData\Local\Programs\Python\Python39\lib\site-packages\urllib3\util\connection.py", line 95, in create_connection
    raise err
  File "c:\Users\USER\AppData\Local\Programs\Python\Python39\lib\site-packages\urllib3\util\connection.py", line 85, in create_connection
    sock.connect(sa)
socket.timeout: timed out

During handling of the above exception, another exception occurred:

Traceback (most recent call last):
  File "c:\Users\USER\AppData\Local\Programs\Python\Python39\lib\site-packages\botocore\httpsession.py", line 464, in send
    urllib_response = conn.urlopen(
  File "c:\Users\USER\AppData\Local\Programs\Python\Python39\lib\site-packages\urllib3\connectionpool.py", line 801, in urlopen
    retries = retries.increment(
  File "c:\Users\USER\AppData\Local\Programs\Python\Python39\lib\site-packages\urllib3\util\retry.py", line 527, in increment
    raise six.reraise(type(error), error, _stacktrace)
  File "c:\Users\USER\AppData\Local\Programs\Python\Python39\lib\site-packages\urllib3\packages\six.py", line 770, in reraise
    raise value
  File "c:\Users\USER\AppData\Local\Programs\Python\Python39\lib\site-packages\urllib3\connectionpool.py", line 715, in urlopen
    httplib_response = self._make_request(
  File "c:\Users\USER\AppData\Local\Programs\Python\Python39\lib\site-packages\urllib3\connectionpool.py", line 416, in _make_request
    conn.request(method, url, **httplib_request_kw)
  File "c:\Users\USER\AppData\Local\Programs\Python\Python39\lib\site-packages\botocore\awsrequest.py", line 96, in request
    rval = super().request(method, url, body, headers, *args, **kwargs)
  File "c:\Users\USER\AppData\Local\Programs\Python\Python39\lib\site-packages\urllib3\connection.py", line 244, in request
    super(HTTPConnection, self).request(method, url, body=body, headers=headers)
  File "c:\Users\USER\AppData\Local\Programs\Python\Python39\lib\http\client.py", line 1255, in request
    self._send_request(method, url, body, headers, encode_chunked)
  File "c:\Users\USER\AppData\Local\Programs\Python\Python39\lib\http\client.py", line 1301, in _send_request
    self.endheaders(body, encode_chunked=encode_chunked)
  File "c:\Users\USER\AppData\Local\Programs\Python\Python39\lib\http\client.py", line 1250, in endheaders
    self._send_output(message_body, encode_chunked=encode_chunked)
  File "c:\Users\USER\AppData\Local\Programs\Python\Python39\lib\site-packages\botocore\awsrequest.py", line 123, in _send_output
    self.send(msg)
  File "c:\Users\USER\AppData\Local\Programs\Python\Python39\lib\site-packages\botocore\awsrequest.py", line 223, in send
    return super().send(str)
  File "c:\Users\USER\AppData\Local\Programs\Python\Python39\lib\http\client.py", line 950, in send
    self.connect()
  File "c:\Users\USER\AppData\Local\Programs\Python\Python39\lib\site-packages\urllib3\connection.py", line 205, in connect
    conn = self._new_conn()
  File "c:\Users\USER\AppData\Local\Programs\Python\Python39\lib\site-packages\urllib3\connection.py", line 179, in _new_conn
    raise ConnectTimeoutError(
urllib3.exceptions.ConnectTimeoutError: (<botocore.awsrequest.AWSHTTPConnection object at 0x00000210840A0D30>, 'Connection to 169.254.169.254 timed out. (connect timeout=1)')

During handling of the above exception, another exception occurred:

Traceback (most recent call last):
  File "c:\Users\USER\AppData\Local\Programs\Python\Python39\lib\site-packages\botocore\utils.py", line 458, in _fetch_metadata_token
    response = self._session.send(request.prepare())
  File "c:\Users\USER\AppData\Local\Programs\Python\Python39\lib\site-packages\botocore\httpsession.py", line 499, in send
    raise ConnectTimeoutError(endpoint_url=request.url, error=e)
botocore.exceptions.ConnectTimeoutError: Connect timeout on endpoint URL: "http://169.254.169.254/latest/api/token"
2024-08-29 15:48:54,049 - urllib3.connectionpool - DEBUG - Starting new HTTP connection (2): 169.254.169.254:80
2024-08-29 15:48:55,051 - botocore.utils - DEBUG - Caught retryable HTTP exception while making metadata service request to http://169.254.169.254/latest/meta-data/iam/security-credentials/: Connect timeout on endpoint URL: "http://169.254.169.254/latest/meta-data/iam/security-credentials/"
Traceback (most recent call last):
  File "c:\Users\USER\AppData\Local\Programs\Python\Python39\lib\site-packages\urllib3\connection.py", line 174, in _new_conn
    conn = connection.create_connection(
  File "c:\Users\USER\AppData\Local\Programs\Python\Python39\lib\site-packages\urllib3\util\connection.py", line 95, in create_connection
    raise err
  File "c:\Users\USER\AppData\Local\Programs\Python\Python39\lib\site-packages\urllib3\util\connection.py", line 85, in create_connection
    sock.connect(sa)
socket.timeout: timed out

During handling of the above exception, another exception occurred:

Traceback (most recent call last):
  File "c:\Users\USER\AppData\Local\Programs\Python\Python39\lib\site-packages\botocore\httpsession.py", line 464, in send
    urllib_response = conn.urlopen(
  File "c:\Users\USER\AppData\Local\Programs\Python\Python39\lib\site-packages\urllib3\connectionpool.py", line 801, in urlopen
    retries = retries.increment(
  File "c:\Users\USER\AppData\Local\Programs\Python\Python39\lib\site-packages\urllib3\util\retry.py", line 527, in increment
    raise six.reraise(type(error), error, _stacktrace)
  File "c:\Users\USER\AppData\Local\Programs\Python\Python39\lib\site-packages\urllib3\packages\six.py", line 770, in reraise
    raise value
  File "c:\Users\USER\AppData\Local\Programs\Python\Python39\lib\site-packages\urllib3\connectionpool.py", line 715, in urlopen
    httplib_response = self._make_request(
  File "c:\Users\USER\AppData\Local\Programs\Python\Python39\lib\site-packages\urllib3\connectionpool.py", line 416, in _make_request
    conn.request(method, url, **httplib_request_kw)
  File "c:\Users\USER\AppData\Local\Programs\Python\Python39\lib\site-packages\botocore\awsrequest.py", line 96, in request
    rval = super().request(method, url, body, headers, *args, **kwargs)
  File "c:\Users\USER\AppData\Local\Programs\Python\Python39\lib\site-packages\urllib3\connection.py", line 244, in request
    super(HTTPConnection, self).request(method, url, body=body, headers=headers)
  File "c:\Users\USER\AppData\Local\Programs\Python\Python39\lib\http\client.py", line 1255, in request
    self._send_request(method, url, body, headers, encode_chunked)
  File "c:\Users\USER\AppData\Local\Programs\Python\Python39\lib\http\client.py", line 1301, in _send_request
    self.endheaders(body, encode_chunked=encode_chunked)
  File "c:\Users\USER\AppData\Local\Programs\Python\Python39\lib\http\client.py", line 1250, in endheaders
    self._send_output(message_body, encode_chunked=encode_chunked)
  File "c:\Users\USER\AppData\Local\Programs\Python\Python39\lib\site-packages\botocore\awsrequest.py", line 123, in _send_output
    self.send(msg)
  File "c:\Users\USER\AppData\Local\Programs\Python\Python39\lib\site-packages\botocore\awsrequest.py", line 223, in send
    return super().send(str)
  File "c:\Users\USER\AppData\Local\Programs\Python\Python39\lib\http\client.py", line 950, in send
    self.connect()
  File "c:\Users\USER\AppData\Local\Programs\Python\Python39\lib\site-packages\urllib3\connection.py", line 205, in connect
    conn = self._new_conn()
  File "c:\Users\USER\AppData\Local\Programs\Python\Python39\lib\site-packages\urllib3\connection.py", line 179, in _new_conn
    raise ConnectTimeoutError(
urllib3.exceptions.ConnectTimeoutError: (<botocore.awsrequest.AWSHTTPConnection object at 0x00000210839E4E80>, 'Connection to 169.254.169.254 timed out. (connect timeout=1)')

During handling of the above exception, another exception occurred:

Traceback (most recent call last):
  File "c:\Users\USER\AppData\Local\Programs\Python\Python39\lib\site-packages\botocore\utils.py", line 513, in _get_request
    response = self._session.send(request.prepare())
  File "c:\Users\USER\AppData\Local\Programs\Python\Python39\lib\site-packages\botocore\httpsession.py", line 499, in send
    raise ConnectTimeoutError(endpoint_url=request.url, error=e)
botocore.exceptions.ConnectTimeoutError: Connect timeout on endpoint URL: "http://169.254.169.254/latest/meta-data/iam/security-credentials/"
2024-08-29 15:48:55,052 - botocore.utils - DEBUG - Max number of attempts exceeded (1) when attempting to retrieve data from metadata service.
2024-08-29 15:48:55,054 - botocore.loaders - DEBUG - Loading JSON file: c:\Users\USER\AppData\Local\Programs\Python\Python39\lib\site-packages\botocore\data\endpoints.json
2024-08-29 15:48:55,070 - botocore.loaders - DEBUG - Loading JSON file: c:\Users\USER\AppData\Local\Programs\Python\Python39\lib\site-packages\botocore\data\sdk-default-configuration.json
2024-08-29 15:48:55,070 - botocore.hooks - DEBUG - Event choose-service-name: calling handler <function handle_service_name_alias at 0x0000021083FD5280>
2024-08-29 15:48:55,105 - botocore.loaders - DEBUG - Loading JSON file: c:\Users\USER\AppData\Local\Programs\Python\Python39\lib\site-packages\botocore\data\sts\2011-06-15\service-2.json.gz
2024-08-29 15:48:55,141 - botocore.loaders - DEBUG - Loading JSON file: c:\Users\USER\AppData\Local\Programs\Python\Python39\lib\site-packages\botocore\data\sts\2011-06-15\endpoint-rule-set-1.json.gz
2024-08-29 15:48:55,142 - botocore.loaders - DEBUG - Loading JSON file: c:\Users\USER\AppData\Local\Programs\Python\Python39\lib\site-packages\botocore\data\partitions.json
2024-08-29 15:48:55,142 - botocore.hooks - DEBUG - Event creating-client-class.sts: calling handler <function add_generate_presigned_url at 0x0000021083F47280>
2024-08-29 15:48:55,143 - botocore.configprovider - DEBUG - Looking for endpoint for sts via: environment_service
2024-08-29 15:48:55,143 - botocore.configprovider - DEBUG - Looking for endpoint for sts via: environment_global
2024-08-29 15:48:55,143 - botocore.configprovider - DEBUG - Looking for endpoint for sts via: config_service
2024-08-29 15:48:55,143 - botocore.configprovider - DEBUG - Looking for endpoint for sts via: config_global
2024-08-29 15:48:55,143 - botocore.configprovider - DEBUG - No configured endpoint found.
2024-08-29 15:48:55,144 - botocore.endpoint - DEBUG - Setting sts timeout as (60, 60)
2024-08-29 15:48:55,145 - botocore.loaders - DEBUG - Loading JSON file: c:\Users\USER\AppData\Local\Programs\Python\Python39\lib\site-packages\botocore\data\_retry.json
2024-08-29 15:48:55,145 - botocore.client - DEBUG - Registering retry handlers for service: sts
2024-08-29 15:48:55,145 - botocore.hooks - DEBUG - Event before-parameter-build.sts.GetCallerIdentity: calling handler <function generate_idempotent_uuid at 0x0000021083FF0C10>
2024-08-29 15:48:55,145 - botocore.regions - DEBUG - Calling endpoint provider with parameters: {'Region': 'aws-global', 'UseDualStack': False, 'UseFIPS': False, 'UseGlobalEndpoint': True}
2024-08-29 15:48:55,146 - botocore.regions - DEBUG - Endpoint provider result: https://sts.amazonaws.com
2024-08-29 15:48:55,146 - botocore.regions - DEBUG - Selecting from endpoint provider's list of auth schemes: "sigv4". User selected auth scheme is: "None"
2024-08-29 15:48:55,146 - botocore.regions - DEBUG - Selected auth type "v4" as "v4" with signing context params: {'region': 'us-east-1', 'signing_name': 'sts'}
2024-08-29 15:48:55,146 - botocore.hooks - DEBUG - Event before-call.sts.GetCallerIdentity: calling handler <function add_recursion_detection_header at 0x0000021083FF0820>
2024-08-29 15:48:55,146 - botocore.hooks - DEBUG - Event before-call.sts.GetCallerIdentity: calling handler <function inject_api_version_header_if_needed at 0x0000021083FF94C0>
2024-08-29 15:48:55,146 - botocore.endpoint - DEBUG - Making request for OperationModel(name=GetCallerIdentity) with params: {'url_path': '/', 'query_string': '', 'method': 'POST', 'headers': {'Content-Type': 'application/x-www-form-urlencoded; charset=utf-8', 'User-Agent': 'Boto3/1.35.5 md/Botocore#1.35.5 ua/2.0 os/windows#10 md/arch#amd64 lang/python#3.9.2rc1 md/pyimpl#CPython cfg/retry-mode#legacy Botocore/1.35.5'}, 'body': {'Action': 'GetCallerIdentity', 'Version': '2011-06-15'}, 'url': 'https://sts.amazonaws.com/', 'context': {'client_region': 'aws-global', 'client_config': <botocore.config.Config object at 0x00000210840B5970>, 'has_streaming_input': False, 'auth_type': 'v4', 'unsigned_payload': None, 'signing': {'region': 'us-east-1', 'signing_name': 'sts'}, 'endpoint_properties': {'authSchemes': [{'name': 'sigv4', 'signingName': 'sts', 'signingRegion': 'us-east-1'}]}}}
2024-08-29 15:48:55,146 - botocore.hooks - DEBUG - Event request-created.sts.GetCallerIdentity: calling handler <bound method RequestSigner.handler of <botocore.signers.RequestSigner object at 0x00000210840B5670>>
2024-08-29 15:48:55,146 - botocore.hooks - DEBUG - Event choose-signer.sts.GetCallerIdentity: calling handler <function set_operation_specific_signer at 0x0000021083FF0A60>
2024-08-29 15:48:55,147 - httpx - DEBUG - load_ssl_context verify=False cert=None trust_env=True http2=False
2024-08-29 15:48:55,147 - httpcore.connection - DEBUG - connect_tcp.started host='127.0.0.1' port=7860 local_address=None timeout=3 socket_options=None
2024-08-29 15:48:55,148 - httpcore.connection - DEBUG - connect_tcp.complete return_value=<httpcore._backends.sync.SyncStream object at 0x0000021083B0A5E0>
2024-08-29 15:48:55,148 - httpcore.http11 - DEBUG - send_request_headers.started request=<Request [b'HEAD']>
2024-08-29 15:48:55,148 - httpcore.http11 - DEBUG - send_request_headers.complete
2024-08-29 15:48:55,148 - httpcore.http11 - DEBUG - send_request_body.started request=<Request [b'HEAD']>
2024-08-29 15:48:55,148 - httpcore.http11 - DEBUG - send_request_body.complete
2024-08-29 15:48:55,149 - httpcore.http11 - DEBUG - receive_response_headers.started request=<Request [b'HEAD']>
2024-08-29 15:48:55,158 - httpcore.http11 - DEBUG - receive_response_headers.complete return_value=(b'HTTP/1.1', 200, b'OK', [(b'date', b'Thu, 29 Aug 2024 06:48:55 GMT'), (b'server', b'uvicorn'), (b'content-length', b'8058'), (b'content-type', b'text/html; charset=utf-8')])
2024-08-29 15:48:55,159 - httpx - INFO - HTTP Request: HEAD http://127.0.0.1:7860/ "HTTP/1.1 200 OK"
2024-08-29 15:48:55,159 - httpcore.http11 - DEBUG - receive_response_body.started request=<Request [b'HEAD']>
2024-08-29 15:48:55,159 - httpcore.http11 - DEBUG - receive_response_body.complete
2024-08-29 15:48:55,159 - httpcore.http11 - DEBUG - response_closed.started
2024-08-29 15:48:55,159 - httpcore.http11 - DEBUG - response_closed.complete
2024-08-29 15:48:55,159 - httpcore.connection - DEBUG - close.started
2024-08-29 15:48:55,159 - httpcore.connection - DEBUG - close.complete
2024-08-29 15:48:55,165 - urllib3.connectionpool - DEBUG - Starting new HTTPS connection (1): huggingface.co:443
2024-08-29 15:48:55,389 - urllib3.connectionpool - DEBUG - https://huggingface.co:443 "HEAD /api/telemetry/gradio/launched HTTP/1.1" 200 0
2024-08-29 15:49:02,571 - matplotlib - DEBUG - matplotlib data path: c:\Users\USER\AppData\Local\Programs\Python\Python39\lib\site-packages\matplotlib\mpl-data
2024-08-29 15:49:02,574 - matplotlib - DEBUG - CONFIGDIR=C:\Users\USER\.matplotlib
2024-08-29 15:49:02,587 - matplotlib - DEBUG - interactive is False
2024-08-29 15:49:02,588 - matplotlib - DEBUG - platform is win32
2024-08-29 15:49:02,595 - urllib3.connectionpool - DEBUG - Starting new HTTPS connection (1): eastus.api.cognitive.microsoft.com:443
2024-08-29 15:49:03,407 - urllib3.connectionpool - DEBUG - https://eastus.api.cognitive.microsoft.com:443 "POST /sts/v1.0/issueToken HTTP/1.1" 200 750
2024-08-29 15:49:03,412 - urllib3.connectionpool - DEBUG - Starting new HTTPS connection (1): eastus.tts.speech.microsoft.com:443
2024-08-29 15:49:39,774 - httpx - DEBUG - load_ssl_context verify=True cert=None trust_env=True http2=False
2024-08-29 15:49:39,775 - httpx - DEBUG - load_verify_locations cafile='c:\\Users\\USER\\AppData\\Local\\Programs\\Python\\Python39\\lib\\site-packages\\certifi\\cacert.pem'
2024-08-29 15:49:39,793 - urllib3.connectionpool - DEBUG - Starting new HTTPS connection (1): huggingface.co:443
2024-08-29 15:49:39,808 - httpcore.connection - DEBUG - connect_tcp.started host='api.gradio.app' port=443 local_address=None timeout=3 socket_options=None
2024-08-29 15:49:39,878 - asyncio - DEBUG - Using selector: SelectSelector
2024-08-29 15:49:39,885 - httpx - DEBUG - load_ssl_context verify=True cert=None trust_env=True http2=False
2024-08-29 15:49:39,886 - httpx - DEBUG - load_verify_locations cafile='c:\\Users\\USER\\AppData\\Local\\Programs\\Python\\Python39\\lib\\site-packages\\certifi\\cacert.pem'
2024-08-29 15:49:39,893 - httpcore.connection - DEBUG - connect_tcp.started host='127.0.0.1' port=7861 local_address=None timeout=None socket_options=None
2024-08-29 15:49:39,893 - httpcore.connection - DEBUG - connect_tcp.complete return_value=<httpcore._backends.sync.SyncStream object at 0x00000210DAB1F730>
2024-08-29 15:49:39,894 - httpcore.http11 - DEBUG - send_request_headers.started request=<Request [b'GET']>
2024-08-29 15:49:39,895 - httpcore.http11 - DEBUG - send_request_headers.complete
2024-08-29 15:49:39,895 - httpcore.http11 - DEBUG - send_request_body.started request=<Request [b'GET']>
2024-08-29 15:49:39,895 - httpcore.http11 - DEBUG - send_request_body.complete
2024-08-29 15:49:39,895 - httpcore.http11 - DEBUG - receive_response_headers.started request=<Request [b'GET']>
2024-08-29 15:49:39,895 - httpcore.http11 - DEBUG - receive_response_headers.complete return_value=(b'HTTP/1.1', 200, b'OK', [(b'date', b'Thu, 29 Aug 2024 06:49:39 GMT'), (b'server', b'uvicorn'), (b'content-length', b'4'), (b'content-type', b'application/json')])
2024-08-29 15:49:39,895 - httpx - INFO - HTTP Request: GET http://127.0.0.1:7861/startup-events "HTTP/1.1 200 OK"
2024-08-29 15:49:39,895 - httpcore.http11 - DEBUG - receive_response_body.started request=<Request [b'GET']>
2024-08-29 15:49:39,895 - httpcore.http11 - DEBUG - receive_response_body.complete
2024-08-29 15:49:39,895 - httpcore.http11 - DEBUG - response_closed.started
2024-08-29 15:49:39,895 - httpcore.http11 - DEBUG - response_closed.complete
2024-08-29 15:49:39,896 - httpcore.connection - DEBUG - close.started
2024-08-29 15:49:39,896 - httpcore.connection - DEBUG - close.complete
2024-08-29 15:49:39,907 - botocore.credentials - DEBUG - Looking for credentials via: env
2024-08-29 15:49:39,907 - botocore.credentials - DEBUG - Looking for credentials via: assume-role
2024-08-29 15:49:39,908 - botocore.credentials - DEBUG - Looking for credentials via: assume-role-with-web-identity
2024-08-29 15:49:39,908 - botocore.credentials - DEBUG - Looking for credentials via: sso
2024-08-29 15:49:39,908 - botocore.credentials - DEBUG - Looking for credentials via: shared-credentials-file
2024-08-29 15:49:39,908 - botocore.credentials - DEBUG - Looking for credentials via: custom-process
2024-08-29 15:49:39,908 - botocore.credentials - DEBUG - Looking for credentials via: config-file
2024-08-29 15:49:39,908 - botocore.credentials - DEBUG - Looking for credentials via: ec2-credentials-file
2024-08-29 15:49:39,908 - botocore.credentials - DEBUG - Looking for credentials via: boto-config
2024-08-29 15:49:39,908 - botocore.credentials - DEBUG - Looking for credentials via: container-role
2024-08-29 15:49:39,908 - botocore.credentials - DEBUG - Looking for credentials via: iam-role
2024-08-29 15:49:39,908 - urllib3.connectionpool - DEBUG - Starting new HTTP connection (3): 169.254.169.254:80
2024-08-29 15:49:39,982 - httpcore.connection - DEBUG - connect_tcp.complete return_value=<httpcore._backends.sync.SyncStream object at 0x0000021083AAEBE0>
2024-08-29 15:49:39,984 - httpcore.connection - DEBUG - start_tls.started ssl_context=<ssl.SSLContext object at 0x00000210848215C0> server_hostname='api.gradio.app' timeout=3
2024-08-29 15:49:40,107 - urllib3.connectionpool - DEBUG - https://huggingface.co:443 "HEAD /api/telemetry/gradio/initiated HTTP/1.1" 200 0
2024-08-29 15:49:40,316 - httpcore.connection - DEBUG - start_tls.complete return_value=<httpcore._backends.sync.SyncStream object at 0x0000021083B6F2B0>
2024-08-29 15:49:40,316 - httpcore.http11 - DEBUG - send_request_headers.started request=<Request [b'GET']>
2024-08-29 15:49:40,316 - httpcore.http11 - DEBUG - send_request_headers.complete
2024-08-29 15:49:40,316 - httpcore.http11 - DEBUG - send_request_body.started request=<Request [b'GET']>
2024-08-29 15:49:40,316 - httpcore.http11 - DEBUG - send_request_body.complete
2024-08-29 15:49:40,316 - httpcore.http11 - DEBUG - receive_response_headers.started request=<Request [b'GET']>
2024-08-29 15:49:40,484 - httpcore.http11 - DEBUG - receive_response_headers.complete return_value=(b'HTTP/1.1', 200, b'OK', [(b'Date', b'Thu, 29 Aug 2024 06:49:39 GMT'), (b'Content-Type', b'application/json'), (b'Content-Length', b'21'), (b'Connection', b'keep-alive'), (b'Server', b'nginx/1.18.0'), (b'Access-Control-Allow-Origin', b'*')])
2024-08-29 15:49:40,485 - httpx - INFO - HTTP Request: GET https://api.gradio.app/pkg-version "HTTP/1.1 200 OK"
2024-08-29 15:49:40,485 - httpcore.http11 - DEBUG - receive_response_body.started request=<Request [b'GET']>
2024-08-29 15:49:40,485 - httpcore.http11 - DEBUG - receive_response_body.complete
2024-08-29 15:49:40,485 - httpcore.http11 - DEBUG - response_closed.started
2024-08-29 15:49:40,485 - httpcore.http11 - DEBUG - response_closed.complete
2024-08-29 15:49:40,485 - httpcore.connection - DEBUG - close.started
2024-08-29 15:49:40,486 - httpcore.connection - DEBUG - close.complete
2024-08-29 15:49:40,925 - botocore.utils - DEBUG - Caught retryable HTTP exception while making metadata service request to http://169.254.169.254/latest/api/token: Connect timeout on endpoint URL: "http://169.254.169.254/latest/api/token"
Traceback (most recent call last):
  File "c:\Users\USER\AppData\Local\Programs\Python\Python39\lib\site-packages\urllib3\connection.py", line 174, in _new_conn
    conn = connection.create_connection(
  File "c:\Users\USER\AppData\Local\Programs\Python\Python39\lib\site-packages\urllib3\util\connection.py", line 95, in create_connection
    raise err
  File "c:\Users\USER\AppData\Local\Programs\Python\Python39\lib\site-packages\urllib3\util\connection.py", line 85, in create_connection
    sock.connect(sa)
socket.timeout: timed out

During handling of the above exception, another exception occurred:

Traceback (most recent call last):
  File "c:\Users\USER\AppData\Local\Programs\Python\Python39\lib\site-packages\botocore\httpsession.py", line 464, in send
    urllib_response = conn.urlopen(
  File "c:\Users\USER\AppData\Local\Programs\Python\Python39\lib\site-packages\urllib3\connectionpool.py", line 801, in urlopen
    retries = retries.increment(
  File "c:\Users\USER\AppData\Local\Programs\Python\Python39\lib\site-packages\urllib3\util\retry.py", line 527, in increment
    raise six.reraise(type(error), error, _stacktrace)
  File "c:\Users\USER\AppData\Local\Programs\Python\Python39\lib\site-packages\urllib3\packages\six.py", line 770, in reraise
    raise value
  File "c:\Users\USER\AppData\Local\Programs\Python\Python39\lib\site-packages\urllib3\connectionpool.py", line 715, in urlopen
    httplib_response = self._make_request(
  File "c:\Users\USER\AppData\Local\Programs\Python\Python39\lib\site-packages\urllib3\connectionpool.py", line 416, in _make_request
    conn.request(method, url, **httplib_request_kw)
  File "c:\Users\USER\AppData\Local\Programs\Python\Python39\lib\site-packages\botocore\awsrequest.py", line 96, in request
    rval = super().request(method, url, body, headers, *args, **kwargs)
  File "c:\Users\USER\AppData\Local\Programs\Python\Python39\lib\site-packages\urllib3\connection.py", line 244, in request
    super(HTTPConnection, self).request(method, url, body=body, headers=headers)
  File "c:\Users\USER\AppData\Local\Programs\Python\Python39\lib\http\client.py", line 1255, in request
    self._send_request(method, url, body, headers, encode_chunked)
  File "c:\Users\USER\AppData\Local\Programs\Python\Python39\lib\http\client.py", line 1301, in _send_request
    self.endheaders(body, encode_chunked=encode_chunked)
  File "c:\Users\USER\AppData\Local\Programs\Python\Python39\lib\http\client.py", line 1250, in endheaders
    self._send_output(message_body, encode_chunked=encode_chunked)
  File "c:\Users\USER\AppData\Local\Programs\Python\Python39\lib\site-packages\botocore\awsrequest.py", line 123, in _send_output
    self.send(msg)
  File "c:\Users\USER\AppData\Local\Programs\Python\Python39\lib\site-packages\botocore\awsrequest.py", line 223, in send
    return super().send(str)
  File "c:\Users\USER\AppData\Local\Programs\Python\Python39\lib\http\client.py", line 950, in send
    self.connect()
  File "c:\Users\USER\AppData\Local\Programs\Python\Python39\lib\site-packages\urllib3\connection.py", line 205, in connect
    conn = self._new_conn()
  File "c:\Users\USER\AppData\Local\Programs\Python\Python39\lib\site-packages\urllib3\connection.py", line 179, in _new_conn
    raise ConnectTimeoutError(
urllib3.exceptions.ConnectTimeoutError: (<botocore.awsrequest.AWSHTTPConnection object at 0x00000210DAB1F9D0>, 'Connection to 169.254.169.254 timed out. (connect timeout=1)')

During handling of the above exception, another exception occurred:

Traceback (most recent call last):
  File "c:\Users\USER\AppData\Local\Programs\Python\Python39\lib\site-packages\botocore\utils.py", line 458, in _fetch_metadata_token
    response = self._session.send(request.prepare())
  File "c:\Users\USER\AppData\Local\Programs\Python\Python39\lib\site-packages\botocore\httpsession.py", line 499, in send
    raise ConnectTimeoutError(endpoint_url=request.url, error=e)
botocore.exceptions.ConnectTimeoutError: Connect timeout on endpoint URL: "http://169.254.169.254/latest/api/token"
2024-08-29 15:49:40,927 - urllib3.connectionpool - DEBUG - Starting new HTTP connection (4): 169.254.169.254:80
2024-08-29 15:49:41,939 - botocore.utils - DEBUG - Caught retryable HTTP exception while making metadata service request to http://169.254.169.254/latest/meta-data/iam/security-credentials/: Connect timeout on endpoint URL: "http://169.254.169.254/latest/meta-data/iam/security-credentials/"
Traceback (most recent call last):
  File "c:\Users\USER\AppData\Local\Programs\Python\Python39\lib\site-packages\urllib3\connection.py", line 174, in _new_conn
    conn = connection.create_connection(
  File "c:\Users\USER\AppData\Local\Programs\Python\Python39\lib\site-packages\urllib3\util\connection.py", line 95, in create_connection
    raise err
  File "c:\Users\USER\AppData\Local\Programs\Python\Python39\lib\site-packages\urllib3\util\connection.py", line 85, in create_connection
    sock.connect(sa)
socket.timeout: timed out

During handling of the above exception, another exception occurred:

Traceback (most recent call last):
  File "c:\Users\USER\AppData\Local\Programs\Python\Python39\lib\site-packages\botocore\httpsession.py", line 464, in send
    urllib_response = conn.urlopen(
  File "c:\Users\USER\AppData\Local\Programs\Python\Python39\lib\site-packages\urllib3\connectionpool.py", line 801, in urlopen
    retries = retries.increment(
  File "c:\Users\USER\AppData\Local\Programs\Python\Python39\lib\site-packages\urllib3\util\retry.py", line 527, in increment
    raise six.reraise(type(error), error, _stacktrace)
  File "c:\Users\USER\AppData\Local\Programs\Python\Python39\lib\site-packages\urllib3\packages\six.py", line 770, in reraise
    raise value
  File "c:\Users\USER\AppData\Local\Programs\Python\Python39\lib\site-packages\urllib3\connectionpool.py", line 715, in urlopen
    httplib_response = self._make_request(
  File "c:\Users\USER\AppData\Local\Programs\Python\Python39\lib\site-packages\urllib3\connectionpool.py", line 416, in _make_request
    conn.request(method, url, **httplib_request_kw)
  File "c:\Users\USER\AppData\Local\Programs\Python\Python39\lib\site-packages\botocore\awsrequest.py", line 96, in request
    rval = super().request(method, url, body, headers, *args, **kwargs)
  File "c:\Users\USER\AppData\Local\Programs\Python\Python39\lib\site-packages\urllib3\connection.py", line 244, in request
    super(HTTPConnection, self).request(method, url, body=body, headers=headers)
  File "c:\Users\USER\AppData\Local\Programs\Python\Python39\lib\http\client.py", line 1255, in request
    self._send_request(method, url, body, headers, encode_chunked)
  File "c:\Users\USER\AppData\Local\Programs\Python\Python39\lib\http\client.py", line 1301, in _send_request
    self.endheaders(body, encode_chunked=encode_chunked)
  File "c:\Users\USER\AppData\Local\Programs\Python\Python39\lib\http\client.py", line 1250, in endheaders
    self._send_output(message_body, encode_chunked=encode_chunked)
  File "c:\Users\USER\AppData\Local\Programs\Python\Python39\lib\site-packages\botocore\awsrequest.py", line 123, in _send_output
    self.send(msg)
  File "c:\Users\USER\AppData\Local\Programs\Python\Python39\lib\site-packages\botocore\awsrequest.py", line 223, in send
    return super().send(str)
  File "c:\Users\USER\AppData\Local\Programs\Python\Python39\lib\http\client.py", line 950, in send
    self.connect()
  File "c:\Users\USER\AppData\Local\Programs\Python\Python39\lib\site-packages\urllib3\connection.py", line 205, in connect
    conn = self._new_conn()
  File "c:\Users\USER\AppData\Local\Programs\Python\Python39\lib\site-packages\urllib3\connection.py", line 179, in _new_conn
    raise ConnectTimeoutError(
urllib3.exceptions.ConnectTimeoutError: (<botocore.awsrequest.AWSHTTPConnection object at 0x00000210DF23F820>, 'Connection to 169.254.169.254 timed out. (connect timeout=1)')

During handling of the above exception, another exception occurred:

Traceback (most recent call last):
  File "c:\Users\USER\AppData\Local\Programs\Python\Python39\lib\site-packages\botocore\utils.py", line 513, in _get_request
    response = self._session.send(request.prepare())
  File "c:\Users\USER\AppData\Local\Programs\Python\Python39\lib\site-packages\botocore\httpsession.py", line 499, in send
    raise ConnectTimeoutError(endpoint_url=request.url, error=e)
botocore.exceptions.ConnectTimeoutError: Connect timeout on endpoint URL: "http://169.254.169.254/latest/meta-data/iam/security-credentials/"
2024-08-29 15:49:41,942 - botocore.utils - DEBUG - Max number of attempts exceeded (1) when attempting to retrieve data from metadata service.
2024-08-29 15:49:41,943 - botocore.hooks - DEBUG - Event choose-service-name: calling handler <function handle_service_name_alias at 0x0000021083FD5280>
2024-08-29 15:49:41,943 - botocore.hooks - DEBUG - Event creating-client-class.sts: calling handler <function add_generate_presigned_url at 0x0000021083F47280>
2024-08-29 15:49:41,943 - botocore.configprovider - DEBUG - Looking for endpoint for sts via: environment_service
2024-08-29 15:49:41,943 - botocore.configprovider - DEBUG - Looking for endpoint for sts via: environment_global
2024-08-29 15:49:41,943 - botocore.configprovider - DEBUG - Looking for endpoint for sts via: config_service
2024-08-29 15:49:41,944 - botocore.configprovider - DEBUG - Looking for endpoint for sts via: config_global
2024-08-29 15:49:41,944 - botocore.configprovider - DEBUG - No configured endpoint found.
2024-08-29 15:49:41,949 - botocore.endpoint - DEBUG - Setting sts timeout as (60, 60)
2024-08-29 15:49:41,950 - botocore.client - DEBUG - Registering retry handlers for service: sts
2024-08-29 15:49:41,950 - botocore.hooks - DEBUG - Event before-parameter-build.sts.GetCallerIdentity: calling handler <function generate_idempotent_uuid at 0x0000021083FF0C10>
2024-08-29 15:49:41,950 - botocore.regions - DEBUG - Calling endpoint provider with parameters: {'Region': 'aws-global', 'UseDualStack': False, 'UseFIPS': False, 'UseGlobalEndpoint': True}
2024-08-29 15:49:41,950 - botocore.regions - DEBUG - Endpoint provider result: https://sts.amazonaws.com
2024-08-29 15:49:41,950 - botocore.regions - DEBUG - Selecting from endpoint provider's list of auth schemes: "sigv4". User selected auth scheme is: "None"
2024-08-29 15:49:41,950 - botocore.regions - DEBUG - Selected auth type "v4" as "v4" with signing context params: {'region': 'us-east-1', 'signing_name': 'sts'}
2024-08-29 15:49:41,950 - botocore.hooks - DEBUG - Event before-call.sts.GetCallerIdentity: calling handler <function add_recursion_detection_header at 0x0000021083FF0820>
2024-08-29 15:49:41,950 - botocore.hooks - DEBUG - Event before-call.sts.GetCallerIdentity: calling handler <function inject_api_version_header_if_needed at 0x0000021083FF94C0>
2024-08-29 15:49:41,950 - botocore.endpoint - DEBUG - Making request for OperationModel(name=GetCallerIdentity) with params: {'url_path': '/', 'query_string': '', 'method': 'POST', 'headers': {'Content-Type': 'application/x-www-form-urlencoded; charset=utf-8', 'User-Agent': 'Boto3/1.35.5 md/Botocore#1.35.5 ua/2.0 os/windows#10 md/arch#amd64 lang/python#3.9.2rc1 md/pyimpl#CPython cfg/retry-mode#legacy Botocore/1.35.5'}, 'body': {'Action': 'GetCallerIdentity', 'Version': '2011-06-15'}, 'url': 'https://sts.amazonaws.com/', 'context': {'client_region': 'aws-global', 'client_config': <botocore.config.Config object at 0x0000021083B65D60>, 'has_streaming_input': False, 'auth_type': 'v4', 'unsigned_payload': None, 'signing': {'region': 'us-east-1', 'signing_name': 'sts'}, 'endpoint_properties': {'authSchemes': [{'name': 'sigv4', 'signingName': 'sts', 'signingRegion': 'us-east-1'}]}}}
2024-08-29 15:49:41,950 - botocore.hooks - DEBUG - Event request-created.sts.GetCallerIdentity: calling handler <bound method RequestSigner.handler of <botocore.signers.RequestSigner object at 0x00000210DF1D0C40>>
2024-08-29 15:49:41,952 - botocore.hooks - DEBUG - Event choose-signer.sts.GetCallerIdentity: calling handler <function set_operation_specific_signer at 0x0000021083FF0A60>
2024-08-29 15:49:41,952 - httpx - DEBUG - load_ssl_context verify=False cert=None trust_env=True http2=False
2024-08-29 15:49:41,952 - httpcore.connection - DEBUG - connect_tcp.started host='127.0.0.1' port=7861 local_address=None timeout=3 socket_options=None
2024-08-29 15:49:41,970 - httpcore.connection - DEBUG - connect_tcp.complete return_value=<httpcore._backends.sync.SyncStream object at 0x0000021083B279A0>
2024-08-29 15:49:41,970 - httpcore.http11 - DEBUG - send_request_headers.started request=<Request [b'HEAD']>
2024-08-29 15:49:41,970 - httpcore.http11 - DEBUG - send_request_headers.complete
2024-08-29 15:49:41,971 - httpcore.http11 - DEBUG - send_request_body.started request=<Request [b'HEAD']>
2024-08-29 15:49:41,971 - httpcore.http11 - DEBUG - send_request_body.complete
2024-08-29 15:49:41,971 - httpcore.http11 - DEBUG - receive_response_headers.started request=<Request [b'HEAD']>
2024-08-29 15:49:41,975 - httpcore.http11 - DEBUG - receive_response_headers.complete return_value=(b'HTTP/1.1', 200, b'OK', [(b'date', b'Thu, 29 Aug 2024 06:49:40 GMT'), (b'server', b'uvicorn'), (b'content-length', b'8068'), (b'content-type', b'text/html; charset=utf-8')])
2024-08-29 15:49:41,975 - httpx - INFO - HTTP Request: HEAD http://127.0.0.1:7861/ "HTTP/1.1 200 OK"
2024-08-29 15:49:41,975 - httpcore.http11 - DEBUG - receive_response_body.started request=<Request [b'HEAD']>
2024-08-29 15:49:41,975 - httpcore.http11 - DEBUG - receive_response_body.complete
2024-08-29 15:49:41,976 - httpcore.http11 - DEBUG - response_closed.started
2024-08-29 15:49:41,976 - httpcore.http11 - DEBUG - response_closed.complete
2024-08-29 15:49:41,976 - httpcore.connection - DEBUG - close.started
2024-08-29 15:49:41,976 - httpcore.connection - DEBUG - close.complete
2024-08-29 15:49:41,984 - urllib3.connectionpool - DEBUG - Starting new HTTPS connection (1): huggingface.co:443
2024-08-29 15:49:42,203 - urllib3.connectionpool - DEBUG - https://huggingface.co:443 "HEAD /api/telemetry/gradio/launched HTTP/1.1" 200 0
2024-08-29 15:49:47,568 - urllib3.connectionpool - DEBUG - Starting new HTTPS connection (1): eastus.api.cognitive.microsoft.com:443
2024-08-29 15:49:48,422 - urllib3.connectionpool - DEBUG - https://eastus.api.cognitive.microsoft.com:443 "POST /sts/v1.0/issueToken HTTP/1.1" 200 750
2024-08-29 15:49:48,430 - urllib3.connectionpool - DEBUG - Starting new HTTPS connection (1): eastus.tts.speech.microsoft.com:443
2024-08-29 15:50:02,591 - urllib3.connectionpool - DEBUG - Starting new HTTPS connection (1): eastus.api.cognitive.microsoft.com:443
2024-08-29 15:50:03,392 - urllib3.connectionpool - DEBUG - https://eastus.api.cognitive.microsoft.com:443 "POST /sts/v1.0/issueToken HTTP/1.1" 200 750
2024-08-29 15:50:03,396 - urllib3.connectionpool - DEBUG - Starting new HTTPS connection (1): eastus.tts.speech.microsoft.com:443
2024-08-29 15:50:04,569 - urllib3.connectionpool - DEBUG - https://eastus.tts.speech.microsoft.com:443 "POST /cognitiveservices/v1 HTTP/1.1" 200 None
